data/sample_orders.csv
ID,Symbol,Side,Price,Quantity
B1,AAPL,BUY,150.25,100
S1,AAPL,SELL,150.5,50
B2,AAPL,BUY,150.3,75
S2,AAPL,SELL,150.4,25
B3,AAPL,BUY,150.2,200
S3,AAPL,SELL,150.6,150
B4,AAPL,BUY,150.35,50
S4,AAPL,SELL,150.45,75
B5,AAPL,BUY,150.12,125
S5,AAPL,SELL,150.55,100
